
<robot name="kuka_robot">
<!-- * * * Link Definitions * * * -->

<link name="camera">
		<visual>
		    <origin xyz="0 0 0" rpy="0 0 0"/>
			<geometry>
				<box size="0.1 0.1 0.1" />
			</geometry>
			
		</visual>
		<collision>
			<geometry>
				<box size="1 1.5 1"/>
				<origin xyz="0 0 0" rpy="0 0 0"/>
				
			</geometry>
		</collision>
		<inertial>
			<mass value="1.0" />
			<origin xyz="0 0 0" rpy="0 0 0"/>
			<inertia ixx="0.0741666666667" ixy="0.0" ixz="0.0" iyy="0.0585416666667" iyz="0.0" izz="0.0260416666667"/>
		</inertial>	
	</link>

 
<joint name="camera_joint" type="revolute">
    	<parent link="base_cylinder4"/>
    	<child link="camera"/>
    	<origin xyz="0 0.3 0" rpy="0 0 0"/>
       	<limit lower="-1.57" upper="1.57" effort="100" velocity="30"/>
        <axis xyz="0 0 1"/>
	</joint>



<gazebo reference="camera">
    <material>Gazebo/Green</material>
    <sensor type="camera" name="camera1">
      <update_rate>30.0</update_rate>
      <camera name="head">
        <horizontal_fov>1.3962634</horizontal_fov>
        <image>
          <width>800</width>
          <height>800</height>
          <format>R8G8B8</format>
        </image>
        <clip>
          <near>0.02</near>
          <far>300</far>
        </clip>
      </camera>
      <plugin name="camera_controller" filename="libgazebo_ros_camera.so">
        <alwaysOn>true</alwaysOn>
        <updateRate>0.0</updateRate>
        <cameraName>mybot/camera1</cameraName>
        <imageTopicName>image_raw</imageTopicName>
        <cameraInfoTopicName>camera_info</cameraInfoTopicName>
        <frameName>camera</frameName>
        <hackBaseline>0.07</hackBaseline>
        <distortionK1>0.0</distortionK1>
        <distortionK2>0.0</distortionK2>
        <distortionK3>0.0</distortionK3>
        <distortionT1>0.0</distortionT1>
        <distortionT2>0.0</distortionT2>
      </plugin>
    </sensor>
  </gazebo>
  <gazebo>
  <plugin name="gazebo_ros_control" filename="libgazebo_ros_control.so">
    <robotNamespace>/MYROBOT</robotNamespace>
    <robotSimType>gazebo_ros_control/DefaultRobotHWSim</robotSimType>
  </plugin>
</gazebo>
</robot>
