<sdf version='1.6'>
  <world name='default'>
    <light name='sun' type='directional'>
      <cast_shadows>1</cast_shadows>
      <pose frame=''>0 0 10 0 -0 0</pose>
      <diffuse>0.8 0.8 0.8 1</diffuse>
      <specular>0.2 0.2 0.2 1</specular>
      <attenuation>
        <range>1000</range>
        <constant>0.9</constant>
        <linear>0.01</linear>
        <quadratic>0.001</quadratic>
      </attenuation>
      <direction>-0.5 0.1 -0.9</direction>
    </light>
    <model name='ground_plane'>
      <static>1</static>
      <link name='link'>
        <collision name='collision'>
          <geometry>
            <plane>
              <normal>0 0 1</normal>
              <size>100 100</size>
            </plane>
          </geometry>
          <surface>
            <contact>
              <collide_bitmask>65535</collide_bitmask>
              <ode/>
            </contact>
            <friction>
              <ode>
                <mu>100</mu>
                <mu2>50</mu2>
              </ode>
              <torsional>
                <ode/>
              </torsional>
            </friction>
            <bounce/>
          </surface>
          <max_contacts>10</max_contacts>
        </collision>
        <visual name='visual'>
          <cast_shadows>0</cast_shadows>
          <geometry>
            <plane>
              <normal>0 0 1</normal>
              <size>100 100</size>
            </plane>
          </geometry>
          <material>
            <script>
              <uri>file://media/materials/scripts/gazebo.material</uri>
              <name>Gazebo/Grey</name>
            </script>
          </material>
        </visual>
        <self_collide>0</self_collide>
        <enable_wind>0</enable_wind>
        <kinematic>0</kinematic>
      </link>
    </model>
    <gravity>0 0 -9.8</gravity>
    <magnetic_field>6e-06 2.3e-05 -4.2e-05</magnetic_field>
    <atmosphere type='adiabatic'/>
    <physics name='default_physics' default='0' type='ode'>
      <max_step_size>0.001</max_step_size>
      <real_time_factor>1</real_time_factor>
      <real_time_update_rate>1000</real_time_update_rate>
    </physics>
    <scene>
      <ambient>0.4 0.4 0.4 1</ambient>
      <background>0.7 0.7 0.7 1</background>
      <shadows>1</shadows>
    </scene>
    <audio>
      <device>default</device>
    </audio>
    <wind/>
    <spherical_coordinates>
      <surface_model>EARTH_WGS84</surface_model>
      <latitude_deg>0</latitude_deg>
      <longitude_deg>0</longitude_deg>
      <elevation>0</elevation>
      <heading_deg>0</heading_deg>
    </spherical_coordinates>
    <model name='myoboat'>
      <link name='base_cylinder1'>
        <pose frame=''>0 0 0 0 -0 0</pose>
        <inertial>
          <pose frame=''>0 0 0.075249 0 -0 0</pose>
          <mass>301</mass>
          <inertia>
            <ixx>21.4889</ixx>
            <ixy>0</ixy>
            <ixz>0</ixz>
            <iyy>20.0641</iyy>
            <iyz>0</iyz>
            <izz>20.026</izz>
          </inertia>
        </inertial>
        <collision name='base_cylinder1_collision'>
          <pose frame=''>0 0 0 0 -0 0</pose>
          <geometry>
            <box>
              <size>1 1.5 1</size>
            </box>
          </geometry>
          <max_contacts>10</max_contacts>
          <surface>
            <contact>
              <ode/>
            </contact>
            <bounce/>
            <friction>
              <torsional>
                <ode/>
              </torsional>
              <ode/>
            </friction>
          </surface>
        </collision>
        <collision name='base_cylinder1_fixed_joint_lump__base_cylinder2_collision_1'>
          <pose frame=''>0 0 0.15 0 -0 0</pose>
          <geometry>
            <box>
              <size>1 1.5 1</size>
            </box>
          </geometry>
          <max_contacts>10</max_contacts>
          <surface>
            <contact>
              <ode/>
            </contact>
            <bounce/>
            <friction>
              <torsional>
                <ode/>
              </torsional>
              <ode/>
            </friction>
          </surface>
        </collision>
        <visual name='base_cylinder1_visual'>
          <pose frame=''>0 0 0.075 0 -0 0</pose>
          <geometry>
            <cylinder>
              <length>0.15</length>
              <radius>0.4</radius>
            </cylinder>
          </geometry>
        </visual>
        <visual name='base_cylinder1_fixed_joint_lump__base_cylinder2_visual_1'>
          <pose frame=''>0 0 0.15 0 -0 0</pose>
          <geometry>
            <cylinder>
              <length>0.15</length>
              <radius>0.3</radius>
            </cylinder>
          </geometry>
        </visual>
        <self_collide>0</self_collide>
        <enable_wind>0</enable_wind>
        <kinematic>0</kinematic>
      </link>
      <link name='base_box1'>
        <pose frame=''>0 -0.02 0.35 0 -0 0</pose>
        <inertial>
          <pose frame=''>0 0 0 0 -0 0</pose>
          <mass>15</mass>
          <inertia>
            <ixx>0.0741667</ixx>
            <ixy>0</ixy>
            <ixz>0</ixz>
            <iyy>0.0585417</iyy>
            <iyz>0</iyz>
            <izz>0.0260417</izz>
          </inertia>
        </inertial>
        <collision name='base_box1_collision'>
          <pose frame=''>0 0 0 0 -0 0</pose>
          <geometry>
            <box>
              <size>1 1.5 1</size>
            </box>
          </geometry>
          <max_contacts>10</max_contacts>
          <surface>
            <contact>
              <ode/>
            </contact>
            <bounce/>
            <friction>
              <torsional>
                <ode/>
              </torsional>
              <ode/>
            </friction>
          </surface>
        </collision>
        <visual name='base_box1_visual'>
          <pose frame=''>0 0 0 0 -0 0</pose>
          <geometry>
            <box>
              <size>0.25 0.5 0.25</size>
            </box>
          </geometry>
        </visual>
        <self_collide>0</self_collide>
        <enable_wind>0</enable_wind>
        <kinematic>0</kinematic>
      </link>
      <joint name='joint2' type='revolute'>
        <child>base_box1</child>
        <parent>base_cylinder1</parent>
        <axis>
          <xyz>0 0 1</xyz>
          <limit>
            <lower>-1.57</lower>
            <upper>1.57</upper>
            <effort>15</effort>
            <velocity>15</velocity>
          </limit>
          <dynamics>
            <spring_reference>0</spring_reference>
            <spring_stiffness>0</spring_stiffness>
          </dynamics>
          <use_parent_model_frame>1</use_parent_model_frame>
        </axis>
      </joint>
      <link name='base_box2'>
        <pose frame=''>0 -0.02 0.35 0 -0 0</pose>
        <inertial>
          <pose frame=''>0 0 0.4 0 -0 0</pose>
          <mass>10</mass>
          <inertia>
            <ixx>0.0741667</ixx>
            <ixy>0</ixy>
            <ixz>0</ixz>
            <iyy>0.0585417</iyy>
            <iyz>0</iyz>
            <izz>0.0260417</izz>
          </inertia>
        </inertial>
        <collision name='base_box2_collision'>
          <pose frame=''>0 0 0 0 -0 0</pose>
          <geometry>
            <box>
              <size>1 1.5 1</size>
            </box>
          </geometry>
          <max_contacts>10</max_contacts>
          <surface>
            <contact>
              <ode/>
            </contact>
            <bounce/>
            <friction>
              <torsional>
                <ode/>
              </torsional>
              <ode/>
            </friction>
          </surface>
        </collision>
        <visual name='base_box2_visual'>
          <pose frame=''>0 0 0.4 0 -0 0</pose>
          <geometry>
            <box>
              <size>0.15 0.15 0.8</size>
            </box>
          </geometry>
        </visual>
        <self_collide>0</self_collide>
        <enable_wind>0</enable_wind>
        <kinematic>0</kinematic>
      </link>
      <joint name='joint3' type='revolute'>
        <child>base_box2</child>
        <parent>base_box1</parent>
        <axis>
          <xyz>1 0 0</xyz>
          <limit>
            <lower>-1.57</lower>
            <upper>1.57</upper>
            <effort>50</effort>
            <velocity>50</velocity>
          </limit>
          <dynamics>
            <spring_reference>0</spring_reference>
            <spring_stiffness>0</spring_stiffness>
          </dynamics>
          <use_parent_model_frame>1</use_parent_model_frame>
        </axis>
      </joint>
      <link name='base_box3'>
        <pose frame=''>0 -0.02 1.15 0 -0 0</pose>
        <inertial>
          <pose frame=''>0 0.325 0 1.57 -0 0</pose>
          <mass>1</mass>
          <inertia>
            <ixx>0.0741667</ixx>
            <ixy>0</ixy>
            <ixz>0</ixz>
            <iyy>0.0585417</iyy>
            <iyz>0</iyz>
            <izz>0.0260417</izz>
          </inertia>
        </inertial>
        <collision name='base_box3_collision'>
          <pose frame=''>0 0 0 0 -0 0</pose>
          <geometry>
            <box>
              <size>1 1.5 1</size>
            </box>
          </geometry>
          <max_contacts>10</max_contacts>
          <surface>
            <contact>
              <ode/>
            </contact>
            <bounce/>
            <friction>
              <torsional>
                <ode/>
              </torsional>
              <ode/>
            </friction>
          </surface>
        </collision>
        <visual name='base_box3_visual'>
          <pose frame=''>0 0.325 0 1.57 -0 0</pose>
          <geometry>
            <box>
              <size>0.15 0.15 0.8</size>
            </box>
          </geometry>
        </visual>
        <self_collide>0</self_collide>
        <enable_wind>0</enable_wind>
        <kinematic>0</kinematic>
      </link>
      <joint name='joint4' type='revolute'>
        <child>base_box3</child>
        <parent>base_box2</parent>
        <axis>
          <xyz>1 0 0</xyz>
          <limit>
            <lower>-1.57</lower>
            <upper>1.57</upper>
            <effort>100</effort>
            <velocity>100</velocity>
          </limit>
          <dynamics>
            <spring_reference>0</spring_reference>
            <spring_stiffness>0</spring_stiffness>
          </dynamics>
          <use_parent_model_frame>1</use_parent_model_frame>
        </axis>
      </joint>
      <link name='base_cylinder3'>
        <pose frame=''>0 0.68 1.15 0 -0 0</pose>
        <inertial>
          <pose frame=''>0 0 0 1.57 -0 0</pose>
          <mass>1</mass>
          <inertia>
            <ixx>0.0741667</ixx>
            <ixy>0</ixy>
            <ixz>0</ixz>
            <iyy>0.0585417</iyy>
            <iyz>0</iyz>
            <izz>0.0260417</izz>
          </inertia>
        </inertial>
        <collision name='base_cylinder3_collision'>
          <pose frame=''>0 0 0 0 -0 0</pose>
          <geometry>
            <box>
              <size>1 1.5 1</size>
            </box>
          </geometry>
          <max_contacts>10</max_contacts>
          <surface>
            <contact>
              <ode/>
            </contact>
            <bounce/>
            <friction>
              <torsional>
                <ode/>
              </torsional>
              <ode/>
            </friction>
          </surface>
        </collision>
        <visual name='base_cylinder3_visual'>
          <pose frame=''>0 0 0 1.57 -0 0</pose>
          <geometry>
            <cylinder>
              <length>0.1</length>
              <radius>0.075</radius>
            </cylinder>
          </geometry>
        </visual>
        <self_collide>0</self_collide>
        <enable_wind>0</enable_wind>
        <kinematic>0</kinematic>
      </link>
      <joint name='joint5' type='revolute'>
        <child>base_cylinder3</child>
        <parent>base_box3</parent>
        <axis>
          <xyz>0 1 0</xyz>
          <limit>
            <lower>-1.57</lower>
            <upper>1.57</upper>
            <effort>100</effort>
            <velocity>50</velocity>
          </limit>
          <dynamics>
            <spring_reference>0</spring_reference>
            <spring_stiffness>0</spring_stiffness>
          </dynamics>
          <use_parent_model_frame>1</use_parent_model_frame>
        </axis>
      </joint>
      <link name='base_box4'>
        <pose frame=''>0 0.68 1.15 0 -0 0</pose>
        <inertial>
          <pose frame=''>0 0.15 0 0 -0 0</pose>
          <mass>2</mass>
          <inertia>
            <ixx>0.153333</ixx>
            <ixy>0</ixy>
            <ixz>0</ixz>
            <iyy>0.0845834</iyy>
            <iyz>2.58806e-05</iyz>
            <izz>0.0895833</izz>
          </inertia>
        </inertial>
        <collision name='base_box4_collision'>
          <pose frame=''>0 0 0 0 -0 0</pose>
          <geometry>
            <box>
              <size>1 1.5 1</size>
            </box>
          </geometry>
          <max_contacts>10</max_contacts>
          <surface>
            <contact>
              <ode/>
            </contact>
            <bounce/>
            <friction>
              <torsional>
                <ode/>
              </torsional>
              <ode/>
            </friction>
          </surface>
        </collision>
        <collision name='base_box4_fixed_joint_lump__base_cylinder4_collision_1'>
          <pose frame=''>0 0 0 0 -0 0</pose>
          <geometry>
            <box>
              <size>1 1.5 1</size>
            </box>
          </geometry>
          <max_contacts>10</max_contacts>
          <surface>
            <contact>
              <ode/>
            </contact>
            <bounce/>
            <friction>
              <torsional>
                <ode/>
              </torsional>
              <ode/>
            </friction>
          </surface>
        </collision>
        <visual name='base_box4_visual'>
          <pose frame=''>0 0.1 0 0 -0 0</pose>
          <geometry>
            <box>
              <size>0.15 0.2 0.1</size>
            </box>
          </geometry>
        </visual>
        <visual name='base_box4_fixed_joint_lump__base_cylinder4_visual_1'>
          <pose frame=''>0 0.2 0 1.57 -0 0</pose>
          <geometry>
            <cylinder>
              <length>0.1</length>
              <radius>0.075</radius>
            </cylinder>
          </geometry>
        </visual>
        <self_collide>0</self_collide>
        <enable_wind>0</enable_wind>
        <kinematic>0</kinematic>
      </link>
      <joint name='joint6' type='revolute'>
        <child>base_box4</child>
        <parent>base_cylinder3</parent>
        <axis>
          <xyz>1 0 0</xyz>
          <limit>
            <lower>-1.57</lower>
            <upper>1.57</upper>
            <effort>100</effort>
            <velocity>50</velocity>
          </limit>
          <dynamics>
            <spring_reference>0</spring_reference>
            <spring_stiffness>0</spring_stiffness>
          </dynamics>
          <use_parent_model_frame>1</use_parent_model_frame>
        </axis>
      </joint>
      <link name='camera'>
        <pose frame=''>0 0.98 1.15 0 -0 0</pose>
        <inertial>
          <pose frame=''>0 0 0 0 -0 0</pose>
          <mass>1</mass>
          <inertia>
            <ixx>0.0741667</ixx>
            <ixy>0</ixy>
            <ixz>0</ixz>
            <iyy>0.0585417</iyy>
            <iyz>0</iyz>
            <izz>0.0260417</izz>
          </inertia>
        </inertial>
        <collision name='camera_collision'>
          <pose frame=''>0 0 0 0 -0 0</pose>
          <geometry>
            <box>
              <size>1 1.5 1</size>
            </box>
          </geometry>
          <surface>
            <contact>
              <ode/>
            </contact>
            <friction>
              <ode/>
              <torsional>
                <ode/>
              </torsional>
            </friction>
            <bounce/>
          </surface>
          <max_contacts>10</max_contacts>
        </collision>
        <visual name='camera_visual'>
          <pose frame=''>0 0 0 0 -0 0</pose>
          <geometry>
            <box>
              <size>0.1 0.1 0.1</size>
            </box>
          </geometry>
          <material>
            <script>
              <name>Gazebo/Green</name>
              <uri>file://media/materials/scripts/gazebo.material</uri>
            </script>
          </material>
        </visual>
        <gravity>1</gravity>
        <velocity_decay/>
        <sensor name='camera1' type='camera'>
          <update_rate>30</update_rate>
          <camera name='head'>
            <horizontal_fov>1.39626</horizontal_fov>
            <image>
              <width>800</width>
              <height>800</height>
              <format>R8G8B8</format>
            </image>
            <clip>
              <near>0.02</near>
              <far>300</far>
            </clip>
          </camera>
          <plugin name='camera_controller' filename='libgazebo_ros_camera.so'>
            <alwaysOn>1</alwaysOn>
            <updateRate>0.0</updateRate>
            <cameraName>mybot/camera1</cameraName>
            <imageTopicName>image_raw</imageTopicName>
            <cameraInfoTopicName>camera_info</cameraInfoTopicName>
            <frameName>camera</frameName>
            <hackBaseline>0.07</hackBaseline>
            <distortionK1>0.0</distortionK1>
            <distortionK2>0.0</distortionK2>
            <distortionK3>0.0</distortionK3>
            <distortionT1>0.0</distortionT1>
            <distortionT2>0.0</distortionT2>
            <robotNamespace>/</robotNamespace>
          </plugin>
        </sensor>
        <self_collide>0</self_collide>
        <enable_wind>0</enable_wind>
        <kinematic>0</kinematic>
      </link>
      <joint name='camera_joint' type='revolute'>
        <child>camera</child>
        <parent>base_box4</parent>
        <axis>
          <xyz>0 0 1</xyz>
          <limit>
            <lower>-1.57</lower>
            <upper>1.57</upper>
            <effort>100</effort>
            <velocity>30</velocity>
          </limit>
          <dynamics>
            <spring_reference>0</spring_reference>
            <spring_stiffness>0</spring_stiffness>
          </dynamics>
          <use_parent_model_frame>1</use_parent_model_frame>
        </axis>
      </joint>
      <static>0</static>
      <plugin name='gazebo_ros_control' filename='libgazebo_ros_control.so'>
        <robotNamespace>/MYROBOT</robotNamespace>
        <robotSimType>gazebo_ros_control/DefaultRobotHWSim</robotSimType>
      </plugin>
      <pose frame=''>0 0 1 0 -0 0</pose>
    </model>
    <model name='suv'>
      <static>1</static>
      <link name='link'>
        <collision name='collision'>
          <pose frame=''>0 0 0 0 0 -1.5708</pose>
          <geometry>
            <mesh>
              <scale>0.06 0.06 0.06</scale>
              <uri>model://suv/meshes/suv.obj</uri>
            </mesh>
          </geometry>
          <max_contacts>10</max_contacts>
          <surface>
            <contact>
              <ode/>
            </contact>
            <bounce/>
            <friction>
              <torsional>
                <ode/>
              </torsional>
              <ode/>
            </friction>
          </surface>
        </collision>
        <visual name='visual'>
          <pose frame=''>0 0 0 0 0 -1.5708</pose>
          <geometry>
            <mesh>
              <scale>0.06 0.06 0.06</scale>
              <uri>model://suv/meshes/suv.obj</uri>
            </mesh>
          </geometry>
        </visual>
        <self_collide>0</self_collide>
        <enable_wind>0</enable_wind>
        <kinematic>0</kinematic>
      </link>
      <pose frame=''>-0.54548 11.8089 0 0 -0 0</pose>
    </model>
    <state world_name='default'>
      <sim_time>95 950000000</sim_time>
      <real_time>213 536413554</real_time>
      <wall_time>1573488745 242221092</wall_time>
      <iterations>95950</iterations>
      <model name='ground_plane'>
        <pose frame=''>0 0 0 0 -0 0</pose>
        <scale>1 1 1</scale>
        <link name='link'>
          <pose frame=''>0 0 0 0 -0 0</pose>
          <velocity>0 0 0 0 -0 0</velocity>
          <acceleration>0 0 0 0 -0 0</acceleration>
          <wrench>0 0 0 0 -0 0</wrench>
        </link>
      </model>
      <model name='myoboat'>
        <pose frame=''>0.17652 0.069864 0.501726 -0.002329 -3.1e-05 0.130434</pose>
        <scale>1 1 1</scale>
        <link name='base_box1'>
          <pose frame=''>0.179041 0.050778 0.851748 -0.001431 0.004388 0.495823</pose>
          <velocity>0.00965 -0.098262 -0.091797 0.364172 -0.657235 0.81592</velocity>
          <acceleration>0.553553 -6.17549 -5.44633 -0.647639 -0.319962 -2.55457</acceleration>
          <wrench>8.3033 -92.6324 -81.6949 0 -0 0</wrench>
        </link>
        <link name='base_box2'>
          <pose frame=''>0.178492 0.063967 0.845338 -0.540692 -0.078954 0.420518</pose>
          <velocity>0.117279 -2.73018 1.18763 2.88371 1.14237 1.96241</velocity>
          <acceleration>-2.27293 -4.30286 -8.34935 0.690833 -0.284393 2.81688</acceleration>
          <wrench>-22.7293 -43.0286 -83.4935 0 -0 0</wrench>
        </link>
        <link name='base_box3'>
          <pose frame=''>-0.03747 0.425896 1.52501 0.426916 -0.030509 0.482105</pose>
          <velocity>-2.47443 6.33951 -4.25821 0.535432 -0.626302 -0.138441</velocity>
          <acceleration>-3.79281 -0.63349 -8.48958 -1.53195 1.36369 -0.355483</acceleration>
          <wrench>-3.79281 -0.63349 -8.48958 0 -0 0</wrench>
        </link>
        <link name='base_box4'>
          <pose frame=''>-0.343583 0.986089 1.8147 2.02035 0.836879 1.03428</pose>
          <velocity>-4.19613 2.51314 0.856004 -2.38095 -0.765763 -1.47388</velocity>
          <acceleration>2.92589 -5.21567 -8.4842 -0.599048 -0.823371 1.55863</acceleration>
          <wrench>5.85178 -10.4313 -16.9684 0 -0 0</wrench>
        </link>
        <link name='base_cylinder1'>
          <pose frame=''>0.17652 0.069864 0.501726 -0.002329 -3.1e-05 0.130434</pose>
          <velocity>0.008775 -0.06425 -0.094017 0.132874 0.023499 -0.004147</velocity>
          <acceleration>0.411846 -4.32697 -5.2383 0.926786 0.443489 0.159831</acceleration>
          <wrench>123.966 -1302.42 -1576.73 0 -0 0</wrench>
        </link>
        <link name='base_cylinder3'>
          <pose frame=''>-0.342882 0.985919 1.81455 0.66705 0.837514 1.03153</pose>
          <velocity>-4.33465 2.54384 0.883875 -1.27741 1.32854 0.640963</velocity>
          <acceleration>-1.03384 -0.503935 -4.48176 0.118409 0.992741 1.5903</acceleration>
          <wrench>-1.03384 -0.503935 -4.48176 0 -0 0</wrench>
        </link>
        <link name='camera'>
          <pose frame=''>-0.129206 1.09192 1.99569 -1.9611 0.696114 -2.70897</pose>
          <velocity>-2.99781 0.351164 0.747198 -1.53531 1.42201 2.64032</velocity>
          <acceleration>6.74574 -9.87269 -12.4234 -3.03465 1.06195 -2.40024</acceleration>
          <wrench>6.74574 -9.87269 -12.4234 0 -0 0</wrench>
        </link>
      </model>
      <model name='suv'>
        <pose frame=''>-0.54548 11.8089 0 0 -0 0</pose>
        <scale>1 1 1</scale>
        <link name='link'>
          <pose frame=''>-0.54548 11.8089 0 0 -0 0</pose>
          <velocity>0 0 0 0 -0 0</velocity>
          <acceleration>0 0 0 0 -0 0</acceleration>
          <wrench>0 0 0 0 -0 0</wrench>
        </link>
      </model>
      <light name='sun'>
        <pose frame=''>0 0 10 0 -0 0</pose>
      </light>
    </state>
    <gui fullscreen='0'>
      <camera name='user_camera'>
        <pose frame=''>15.9148 -18.4131 18.1408 0 0.538623 2.22314</pose>
        <view_controller>orbit</view_controller>
        <projection_type>perspective</projection_type>
      </camera>
    </gui>
  </world>
</sdf>
